<mujoco model="lever_basic">
    <compiler angle="radian" />
    <size njmax="500" nconmax="100" />
    <asset>
        <texture builtin="gradient" height="100" rgb1="1 1 1" rgb2="0 0 0" type="skybox" width="100"/>
        <texture builtin="flat" height="1278" mark="cross" markrgb="1 1 1" name="texgeom" random="0.01" rgb1="0.8 0.6 0.4" rgb2="0.8 0.6 0.4" type="cube" width="127"/>
        <texture builtin="checker" height="100" name="texplane" rgb1="0 0 0" rgb2="0.8 0.8 0.8" type="2d" width="100"/>
        <material name="MatPlane" reflectance="0.5" shininess="1" specular="1" texrepeat="60 60" texture="texplane"/>
        <material name="geom" texture="texgeom" texuniform="true"/>
        
        <mesh name="base-casing" file="base-casing.stl" scale="0.059 0.059 0.059" />
        <mesh name="base-squares-only" file="base-squares-only.stl" scale="0.059 0.059 0.059" />
        <mesh name="lever-arm-colored" file="lever-arm-colored.stl" scale="0.059 0.059 0.059" />
    </asset>
    <worldbody>
        <light cutoff="100" diffuse="1 1 1" dir="-0 0 -1.3" directional="true" exponent="1" pos="0 0 1.3" specular=".1 .1 .1"/>
        <geom conaffinity="1" condim="3" material="MatPlane" name="floor" pos="0 0 0" rgba="0.8 0.9 0.8 1" size="40 40 40" type="plane"/>
        
        <geom pos="0 0 0.015" type="mesh" rgba="0.9 0.9 0.9 1" mesh="base-casing" />
        <geom pos="0 0 0.015" type="mesh" rgba="0 0 0 1" mesh="base-squares-only" />
        <body name="lever_link" pos="0 0 0.015">
            <inertial pos="2.16239e-07 -7.69517e-07 0.0524899" quat="0.707302 -1.54856e-05 8.68889e-06 0.706911" mass="0.0322557" diaginertia="3.53465e-05 3.52275e-05 1.5348e-06" />
            <joint name="squares_to_lever" pos="0 0 0" axis="0 1 0" limited="true" range="-1.57 1.57" />
            <geom type="mesh" rgba="0 0 0 1" mesh="lever-arm-colored" />
        </body>
    </worldbody>
</mujoco>
