<mujoco model="open_manipulator">
    <compiler angle="radian" />
    <size njmax="500" nconmax="100" />
    <asset>
        <texture builtin="gradient" height="100" rgb1="1 1 1" rgb2="0 0 0" type="skybox" width="100"/>
        <texture builtin="flat" height="1278" mark="cross" markrgb="1 1 1" name="texgeom" random="0.01" rgb1="0.8 0.6 0.4" rgb2="0.8 0.6 0.4" type="cube" width="127"/>
        <texture builtin="checker" height="100" name="texplane" rgb1="0 0 0" rgb2="0.8 0.8 0.8" type="2d" width="100"/>
        <material name="MatPlane" reflectance="0.5" shininess="1" specular="1" texrepeat="60 60" texture="texplane"/>
        <material name="geom" texture="texgeom" texuniform="true"/>
        
        <mesh name="chain_link1" file="../meshes/chain_link1.stl" scale="0.001 0.001 0.001" />
        <mesh name="chain_link2" file="../meshes/chain_link2.stl" scale="0.001 0.001 0.001" />
        <mesh name="chain_link3" file="../meshes/chain_link3.stl" scale="0.001 0.001 0.001" />
        <mesh name="chain_link4" file="../meshes/chain_link4.stl" scale="0.001 0.001 0.001" />
        <mesh name="chain_link5" file="../meshes/chain_link5.stl" scale="0.001 0.001 0.001" />
        <mesh name="chain_link_grip_l" file="../meshes/chain_link_grip_l.stl" scale="0.001 0.001 0.001" />
        <mesh name="chain_link_grip_r" file="../meshes/chain_link_grip_r.stl" scale="0.001 0.001 0.001" />
    </asset>
    <worldbody>
        <light cutoff="100" diffuse="1 1 1" dir="-0 0 -1.3" directional="true" exponent="1" pos="0 0 1.3" specular=".1 .1 .1"/>
        <geom conaffinity="1" condim="3" material="MatPlane" name="floor" pos="0 0 0" rgba="0.8 0.9 0.8 1" size="40 40 40" type="plane"/>
        
        <geom type="mesh" mesh="chain_link1" />
        <body name="link2" pos="0.012 0 0.017">
            <inertial pos="-0.000301849 0.000540437 0.0474335" quat="0.999915 0.000960074 0.0122201 -0.00449872" mass="0.0984068" diaginertia="3.4553e-05 3.26892e-05 1.88409e-05" />
            <joint name="joint1" pos="0 0 0" axis="0 0 1" limited="true" range="-3.14159 3.14159" />
            <geom pos="0 0 0.019" type="mesh" mesh="chain_link2" />
            <body name="link3" pos="0 0 0.0595">
                <inertial pos="0.0103084 0.000377434 0.101702" quat="0.71133 0.0466763 0.0513691 0.699423" mass="0.138509" diaginertia="0.000342915 0.000335932 5.49578e-05" />
                <joint name="joint2" pos="0 0 0" axis="0 1 0" limited="true" range="-1.79071 1.5708" />
                <geom type="mesh" mesh="chain_link3" />
                <body name="link4" pos="0.024 0 0.128">
                    <inertial pos="0.0909096 0.000389298 0.000224133" quat="-0.00162881 0.706672 0.0026348 0.707535" mass="0.132746" diaginertia="0.000251551 0.000242311 3.06462e-05" />
                    <joint name="joint3" pos="0 0 0" axis="0 1 0" limited="true" range="-0.942478 1.3823" />
                    <geom type="mesh" mesh="chain_link4" />
                    <body name="link5" pos="0.124 0 0">
                        <inertial pos="0.0447737 3.65846e-07 0.00885244" quat="5.9604e-06 0.701608 -6.05347e-06 0.712564" mass="0.144276" diaginertia="0.000100776 8.37031e-05 8.19451e-05" />
                        <joint name="joint4" pos="0 0 0" axis="0 1 0" limited="true" range="-1.79071 2.04204" />
                        <geom type="mesh" mesh="chain_link5" />
                        <geom size="0.04 0.06 0.06" pos="0.02 0 0" type="box" rgba="0 0 0.8 1" />
                        <body name="gripper_link" pos="0.0817 0.021 0">
                            <inertial pos="0 0 0" mass="0.017" diaginertia="0.001 0.001 0.001" />
                            <joint name="gripper" pos="0 0 0" axis="0 1 0" type="slide" limited="true" range="-0.01 0.019" />
                            <geom type="mesh" mesh="chain_link_grip_l" />
                        </body>
                        <body name="gripper_link_sub" pos="0.0817 -0.021 0">
                            <inertial pos="0 0 0" mass="0.017" diaginertia="0.001 0.001 0.001" />
                            <joint name="gripper_sub" pos="0 0 0" axis="0 -1 0" type="slide" limited="true" range="-0.01 0.019" />
                            <geom type="mesh" mesh="chain_link_grip_r" />
                        </body>
                    </body>
                </body>
            </body>
        </body>
    </worldbody>
</mujoco>
